<mujoco model="S1_urdf">
  <compiler angle="radian"/>

  <asset>
    <mesh name="base_link" file="base_link.STL"/>
    <mesh name="1_Link" file="1_Link.STL"/>
    <mesh name="2_Link" file="2_Link.STL"/>
    <mesh name="3_Link" file="3_Link.STL"/>
    <mesh name="4_Link" file="4_Link.STL"/>
    <mesh name="5_Link" file="5_Link.STL"/>
    <mesh name="6_Link" file="6_Link.STL"/>
    <mesh name="7_1_Link" file="7_1_Link.STL"/>
    <mesh name="7_2_Link" file="7_2_Link.STL"/>
  </asset>

  <worldbody>
    <geom type="mesh" rgba="1 1 1 1" mesh="base_link"/>
    <body name="1_Link">
      <inertial pos="-5e-06 0 0.0590654" quat="0.5 0.5 0.5 0.5" mass="0.240435" diaginertia="0.000186308 0.000164031 0.000128092"/>
      <joint name="1joint" pos="0 0 0" axis="0 0 1" range="-2.967 2.967" actuatorfrcrange="-9 9"/>
      <geom type="mesh" rgba="1 1 1 1" mesh="1_Link"/>
      <body name="2_Link" pos="0 0 0.06525">
        <inertial pos="0.000517956 0.251879 -7.29157e-05" quat="0.496418 0.50451 -0.503702 0.495301" mass="0.27896" diaginertia="0.00101012 0.000968577 0.00016357"/>
        <joint name="2joint" pos="0 0 0" axis="1 0 0" range="0 3.14" actuatorfrcrange="-9 9"/>
        <geom type="mesh" rgba="0.792157 0.819608 0.933333 1" mesh="2_Link"/>
        <body name="3_Link" pos="0.000495 0.3 0">
          <inertial pos="-0.00362159 -0.190378 0.0563752" quat="0.723905 0.689279 -0.00259707 -0.0291389" mass="0.196496" diaginertia="0.000365387 0.000357218 7.49679e-05"/>
          <joint name="3joint" pos="0 0 0" axis="-1 0 0" range="-3.4 0" actuatorfrcrange="-9 9"/>
          <geom type="mesh" rgba="0.796078 0.823529 0.937255 1" mesh="3_Link"/>
          <body name="4_Link" pos="-0.000495 -0.22 0.057">
            <inertial pos="0.00252083 -0.0683945 0.0485252" quat="0.88999 0.422772 -0.02784 -0.168542" mass="0.160912" diaginertia="0.000225826 0.000223253 6.28301e-05"/>
            <joint name="4joint" pos="0 0 0" axis="1 0 0" range="-1.57 1.518" actuatorfrcrange="-3 3"/>
            <geom type="mesh" rgba="1 1 1 1" mesh="4_Link"/>
            <body name="5_Link" pos="0 -0.0807873 0.0591737">
              <inertial pos="-9.47221e-11 -0.000956924 -0.0552063" quat="0.706374 -0.0321127 0.032113 0.706381" mass="0.148471" diaginertia="7.23521e-05 7.08257e-05 6.2135e-05"/>
              <joint name="5joint" pos="0 0 0" axis="0 0 -1" range="-1.57 1.57" actuatorfrcrange="-3 3"/>
              <geom type="mesh" rgba="1 1 1 1" mesh="5_Link"/>
              <body name="6_Link" pos="0 -0.0012127 -0.059174">
                <inertial pos="3.32172e-08 -0.0626158 0.00043456" quat="0.501683 0.498312 0.501683 0.498312" mass="0.191166" diaginertia="0.000155312 0.000139085 5.70486e-05"/>
                <joint name="6joint" pos="0 0 0" axis="0 -1 0" range="-1.57 1.57" actuatorfrcrange="-3 3"/>
                <geom type="mesh" rgba="1 1 1 1" mesh="6_Link"/>
                <body name="7_1_Link" pos="0.0139 -0.1 0.016" quat="0.707388 0.706825 0 0">
                  <inertial pos="3.32172e-08 -0.0626158 0.00043456" quat="0.501683 0.498312 0.501683 0.498312" mass="0.0911655" diaginertia="0.000155312 0.000139085 5.70486e-05"/>
                  <joint name="7joint" pos="0 0 0" axis="1 0 0" type="slide" range="0 0.05" actuatorfrcrange="-3 3"/>
                  <geom type="mesh" rgba="1 1 1 1" mesh="7_1_Link"/>
                </body>
                <body name="7_2_Link" pos="-0.0139 -0.1 -0.016" quat="0.707388 0.706825 0 0">
                  <inertial pos="3.32172e-08 -0.0626158 0.00043456" quat="0.501683 0.498312 0.501683 0.498312" mass="0.0911655" diaginertia="0.000155312 0.000139085 5.70486e-05"/>
                  <joint name="8joint" pos="0 0 0" axis="-1 0 0" type="slide" range="0 0.05" actuatorfrcrange="-3 3"/>
                  <geom type="mesh" rgba="1 1 1 1" mesh="7_2_Link"/>
                </body>
              </body>
            </body>
          </body>
        </body>
      </body>
    </body>
  </worldbody>
    <contact>
    <exclude body1="4_Link" body2="6_Link"/>
    <exclude body1="world" body2="1_Link"/>
  </contact>
</mujoco>
